Workbook

Sheet Model
A1: s
B2: MULTIFAMILY UNDERWRITING MODEL
B3: Comprehensive Analysis with Creative Financing
B5: KEY DEAL METRICS | F5: SOURCES OF FUNDS | J5: USES OF FUNDS | N5: TRADITIONAL LOAN
B6: Property Name | D6: Riverside | F6: Source | G6: Amount | H6: % | J6: Use | K6: Amount | L6: % | N6: Loan Amount
B7: Total Units | D7: Model!D9 | F7: Traditional Loan | G7: =#REF! -> #REF! | H7: =IF($G$12=0,0,G7/$G$12) -> #REF! | J7: Purchase Price | K7: =D9 -> 1000000 | L7: =IF($K$12=0,0,K7/$K$12) -> #REF! | N7: Interest Rate
B8: Total SF | D8: 7948 | F8: Seller Financing | G8: =#REF! -> #REF! | H8: =IF($G$12=0,0,G8/$G$12) -> #REF! | J8: Closing Costs | K8: =#REF! -> #REF! | L8: =IF($K$12=0,0,K8/$K$12) -> #REF! | N8: Term (Months)
B9: Purchase Price | D9: 1000000 | F9: Seller Carryback | G9: =#REF! -> #REF! | H9: =IF($G$12=0,0,G9/$G$12) -> #REF! | J9: Due Diligence | K9: =#REF! -> #REF! | L9: =IF($K$12=0,0,K9/$K$12) -> #REF! | N9: Amortization (Months)
B10: Price Per SF | D10: =D9/D8 -> 125.81782 | F10: LP Equity | G10: =D104 -> #REF! | H10: =IF($G$12=0,0,G10/$G$12) -> #REF! | J10: Financing Costs | K10: =#REF! -> #REF! | L10: =IF($K$12=0,0,K10/$K$12) -> #REF! | N10: Monthly P&I | O10: =IF(O6=0,0,PMT(O7/12,O9,-O6)) -> 0
B11: Year 1 NOI | D11: =E73 -> #REF! | F11: GP Equity | G11: =D105 -> #REF! | H11: =IF($G$12=0,0,G11/$G$12) -> #REF! | J11: Operating Reserves | K11: =#REF! -> #REF! | L11: =IF($K$12=0,0,K11/$K$12) -> #REF! | N11: Annual Debt Service | O11: =O10*12 -> 0
B12: Going-In Cap Rate | D12: =IF(D9=0,0,D11/D9) -> #REF! | F12: Total Sources | G12: =SUM(G7:G11) -> #REF! | H12: =IF($G$12=0,0,G12/$G$12) -> #REF! | J12: Total Uses | K12: =SUM(K7:K11) -> #REF! | L12: =IF($K$12=0,0,K12/$K$12) -> #REF!
B13: Stabilized Cap Rate | D13: Model!D13 | N13: SELLER CARRYBACK / EQUITY PARTNER
B14: ═══════════════════════════════════════════════════════════════════════════════════════════════════════════════ | N14: Loan Amount
N15: Interest Rate
B16: UNIT MIX & RENT ROLL | N16: Term (Months)
B17: Unit # | C17: Type | D17: SF | E17: Status | F17: Market Rent | G17: In-Place Rent | H17: Loss to Lease | N17: Interest-Only (Y/N)
B18: 8 | C18: studio | D18: 300 | E18: rented | F18: 825 | G18: 822 | H18: =F18-G18 -> 3 | N18: Monthly Payment | O18: =IF(O17=1,O14*O15/12,IF(O14=0,0,PMT(O15/12,O16,-O14))) -> 0
B19: 8 | C19: 1bed/1bath | D19: 481 | F19: 950 | G19: 800 | H19: =F19-G19 -> 150 | N19: Annual Debt Service | O19: =O18*12 -> 0
B20: 2 | C20: 2b/2bath | D20: 853 | F20: 1100 | G20: 1025 | H20: =F20-G20 -> 75
H21: =F21-G21 -> 0 | N21: SELLER FINANCING (1ST POSITION)
H22: =F22-G22 -> 0 | N22: Loan Amount
H23: =F23-G23 -> 0 | N23: Interest Rate
H24: =F24-G24 -> 0 | N24: Term (Months)
H25: =F25-G25 -> 0 | N25: Amortization (Months)
H26: =F26-G26 -> 0 | N26: Interest-Only Period (Mo)
H27: =F27-G27 -> 0 | N27: Monthly P&I (after IO) | O27: =IF(O22=0,0,PMT(O23/12,O25,-O22)) -> 0
H28: =F28-G28 -> 0 | N28: Monthly IO Payment | O28: =O22*O23/12 -> 0
B29: TOTALS | D29: =SUM(D18:D28) -> 1634 | F29: =SUM(F18:F28) -> 2875 | G29: =SUM(G18:G28) -> 2647 | H29: =SUM(H18:H28) -> 228 | N29: Annual Debt Service | O29: =IF(O26>0,O28*12,O27*12) -> 0
B31: ═══════════════════════════════════════════════════════════════════════════════════════════════════════════════ | N31: BLENDED FINANCING SUMMARY
N32: Total Debt | O32: =O6+O14+O22 -> 0
B33: REVENUE PROJECTIONS | N33: Total Annual Debt Service | O33: =O11+O19+O29 -> 0
B34: Revenue Item | C34: $/Unit/Mo | D34: Annual | E34: Year 1 | F34: Year 2 | G34: Year 3 | H34: Year 4 | I34: Year 5 | J34: Year 6 | K34: Year 7 | L34: Year 8 | M34: Year 9 | N34: Blended Interest Rate | O34: =IF(O32=0,0,(O6*O7+O14*O15+O22*O23)/O32) -> 0
B35: Gross Potential Rent | C35: =D35/D7/12 -> #VALUE! | D35: =F29*12 -> 34500 | E35: =D35 -> 34500 | F35: =E35*(1+#REF!) -> #REF! | G35: =F35*(1+#REF!) -> #REF! | H35: =G35*(1+#REF!) -> #REF! | I35: =H35*(1+#REF!) -> #REF! | J35: =I35*(1+#REF!) -> #REF! | K35: =J35*(1+#REF!) -> #REF! | L35: =K35*(1+#REF!) -> #REF! | M35: =L35*(1+#REF!) -> #REF! | N35: Debt Yield | O35: =IF(O32=0,0,E73/O32) -> 0
B36: (Less) Vacancy | C36: =-C35*#REF! -> #VALUE! | D36: =-D35*#REF! -> #REF! | E36: =D36 -> #REF! | F36: =-F35*#REF! -> #REF! | G36: =-G35*#REF! -> #REF! | H36: =-H35*#REF! -> #REF! | I36: =-I35*#REF! -> #REF! | J36: =-J35*#REF! -> #REF! | K36: =-K35*#REF! -> #REF! | L36: =-L35*#REF! -> #REF! | M36: =-M35*#REF! -> #REF! | N36: LTV (% of Purchase) | O36: =IF(D9=0,0,O32/D9) -> 0
B37: (Less) Loss to Lease | C37: =D37/D7/12 -> #VALUE! | D37: =-H29*12 -> -2736 | E37: =D37 -> -2736 | F37: =E37*(1-0.1) -> -2462.4 | G37: =F37*(1-0.1) -> -2216.16 | H37: =G37*(1-0.1) -> -1994.544 | I37: =H37*(1-0.1) -> -1795.0896 | J37: =I37*(1-0.1) -> -1615.5806 | K37: =J37*(1-0.1) -> -1454.0226 | L37: =K37*(1-0.1) -> -1308.6203 | M37: =L37*(1-0.1) -> -1177.7583
B38: (Less) Concessions | C38: =-C35*#REF! -> #VALUE! | D38: =-D35*#REF! -> #REF! | E38: =D38 -> #REF! | F38: =-F35*#REF! -> #REF! | G38: =-G35*#REF! -> #REF! | H38: =-H35*#REF! -> #REF! | I38: =-I35*#REF! -> #REF! | J38: =-J35*#REF! -> #REF! | K38: =-K35*#REF! -> #REF! | L38: =-L35*#REF! -> #REF! | M38: =-M35*#REF! -> #REF!
B39: (Less) Bad Debt | C39: =-C35*#REF! -> #VALUE! | D39: =-D35*#REF! -> #REF! | E39: =D39 -> #REF! | F39: =-F35*#REF! -> #REF! | G39: =-G35*#REF! -> #REF! | H39: =-H35*#REF! -> #REF! | I39: =-I35*#REF! -> #REF! | J39: =-J35*#REF! -> #REF! | K39: =-K35*#REF! -> #REF! | L39: =-L35*#REF! -> #REF! | M39: =-M35*#REF! -> #REF!
B40: Net Rental Income | C40: =SUM(C35:C39) -> #VALUE! | D40: =SUM(D35:D39) -> #REF! | E40: =SUM(E35:E39) -> #REF! | F40: =SUM(F35:F39) -> #REF! | G40: =SUM(G35:G39) -> #REF! | H40: =SUM(H35:H39) -> #REF! | I40: =SUM(I35:I39) -> #REF! | J40: =SUM(J35:J39) -> #REF! | ... M40: =SUM(M35:M39) -> #REF!
B43: EFFECTIVE GROSS INCOME | D43: =D40 -> #REF! | E43: =E40 -> #REF! | F43: =F40 -> #REF! | G43: =G40 -> #REF! | H43: =H40 -> #REF! | I43: =I40 -> #REF! | J43: =J40 -> #REF! | K43: =K40 -> #REF! | ... N43: =N40
B45: ═══════════════════════════════════════════════════════════════════════════════════════════════════════════════
...

Sheet RUBS
B2: RATIO UTILITY BILLING SYSTEM (RUBS)
B3: Utility Cost Allocation & Recovery Model
B5: CONFIGURATION | F5: INSTRUCTIONS
B6: Property References | F6: 1. Enter monthly utility costs in the Utility Cost Inputs section (blue cells)
B7: Total Units | C7: =Model!D7 -> Model!D9 | F7: 2. Select allocation method for each utility: SF, Units, or Occupancy
B8: Total SF | C8: =Model!D8 -> 7948 | F8: 3. Enter occupant count per unit in the Unit Detail table (blue cells)
F9: 4. Adjust admin fee settings as needed ($/unit or % markup)
B10: Admin Fee Settings | F10: 5. Review Summary Output for cost recovery analysis
B11: Admin Fee ($/unit/mo) | C11: 5
B12: Admin Fee (% markup) | C12: 0.05 | F12: COLOR LEGEND:
B13: Use Fee Method | C13: $/unit | D13: ($/unit or % markup) | F13: Blue text = User input
B14: Target Recovery % | C14: 1 | F14: Green text = Cross-sheet reference
F15: Black text = Calculated formula
B16: UTILITY COST INPUTS
B17: Utility | C17: Monthly Cost | D17: Annual Cost | E17: Allocation Method | F17: Methods: SF, Units, Occupancy
B18: Water/Sewer | C18: 0 | D18: =C18*12 -> 0 | E18: Units
B19: Electric (Common) | C19: 0 | D19: =C19*12 -> 0 | E19: SF
B20: Gas | C20: 0 | D20: =C20*12 -> 0 | E20: Units
B21: Trash | C21: 0 | D21: =C21*12 -> 0 | E21: Units
B22: Other | C22: 0 | D22: =C22*12 -> 0 | E22: SF
B23: TOTAL | C23: =SUM(C18:C22) -> 0 | D23: =SUM(D18:D22) -> 0
B25: SUMMARY OUTPUT
B26: Cost Recovery | C26: Monthly | D26: Annual
B27: Total Utility Costs | C27: =C23 -> 0 | D27: =D23 -> 0
B28: Total Allocated to Units | C28: =IFERROR(SUM(K44:K54),0) -> 0 | D28: =IFERROR(SUM(L44:L54),0) -> 0
B29: Admin Fees Collected | C29: =IFERROR(IF(C13="$/unit",C11*C7,C12*C28),0) -> 0 | D29: =C29*12 -> 0
B30: Gross Revenue from RUBS | C30: =C28+C29 -> 0 | D30: =D28+D29 -> 0
B31: Net Recovery | C31: =C30-C27 -> 0 | D31: =D30-D27 -> 0
B33: Recovery Metrics
B34: Recovery % Achieved | C34: =IFERROR(C31/C27,0) -> 0 | D34: =IFERROR(D31/D27,0) -> 0
B35: Target Recovery % | C35: =C14 -> 1 | D35: =C14 -> 1
B36: Variance vs Target | C36: =C34-C35 -> -1 | D36: =D34-D35 -> -1
B38: Cost per Unit (Monthly) | C38: =IFERROR(C27/C7,0) -> 0
B39: Cost per SF (Monthly) | C39: =IFERROR(C27/C8,0) -> 0
B40: Revenue per Unit (Monthly) | C40: =IFERROR(C31/C7,0) -> 0
B42: UNIT-LEVEL DETAIL
B43: Unit # | C43: Type | D43: SF | E43: Occupants | F43: Water/Sewer | G43: Electric | H43: Gas | I43: Trash | J43: Other | K43: Total Monthly | L43: Total Annual
B44: =Model!B18 -> 8 | C44: =Model!C18 -> studio | D44: =Model!D18 -> 300 | E44: 2 | F44: =IFERROR(IF($E$18="SF",$C$18*D44/$C$8,IF($E$18="Units",$C$18/$C$7,IF($E$18="Occupancy",$C$18*E44/SUM($E$44:$E$54),$C$18/$C$7))),0) -> 0 | G44: =IFERROR(IF($E$19="SF",$C$19*D44/$C$8,IF($E$19="Units",$C$19/$C$7,IF($E$19="Occupancy",$C$19*E44/SUM($E$44:$E$54),$C$19/$C$7))),0) -> 0 | H44: =IFERROR(IF($E$20="SF",$C$20*D44/$C$8,IF($E$20="Units",$C$20/$C$7,IF($E$20="Occupancy",$C$20*E44/SUM($E$44:$E$54),$C$20/$C$7))),0) -> 0 | I44: =IFERROR(IF($E$21="SF",$C$21*D44/$C$8,IF($E$21="Units",$C$21/$C$7,IF($E$21="Occupancy",$C$21*E44/SUM($E$44:$E$54),$C$21/$C$7))),0) -> 0 | J44: =IFERROR(IF($E$22="SF",$C$22*D44/$C$8,IF($E$22="Units",$C$22/$C$7,IF($E$22="Occupancy",$C$22*E44/SUM($E$44:$E$54),$C$22/$C$7))),0) -> 0 | K44: =SUM(F44:J44) -> 0 | L44: =K44*12 -> 0
B45: =Model!B19 -> 8 | C45: =Model!C19 -> 1bed/1bath | D45: =Model!D19 -> 481 | E45: 2 | F45: =IFERROR(IF($E$18="SF",$C$18*D45/$C$8,IF($E$18="Units",$C$18/$C$7,IF($E$18="Occupancy",$C$18*E45/SUM($E$44:$E$54),$C$18/$C$7))),0) -> 0 | G45: =IFERROR(IF($E$19="SF",$C$19*D45/$C$8,IF($E$19="Units",$C$19/$C$7,IF($E$19="Occupancy",$C$19*E45/SUM($E$44:$E$54),$C$19/$C$7))),0) -> 0 | H45: =IFERROR(IF($E$20="SF",$C$20*D45/$C$8,IF($E$20="Units",$C$20/$C$7,IF($E$20="Occupancy",$C$20*E45/SUM($E$44:$E$54),$C$20/$C$7))),0) -> 0 | I45: =IFERROR(IF($E$21="SF",$C$21*D45/$C$8,IF($E$21="Units",$C$21/$C$7,IF($E$21="Occupancy",$C$21*E45/SUM($E$44:$E$54),$C$21/$C$7))),0) -> 0 | J45: =IFERROR(IF($E$22="SF",$C$22*D45/$C$8,IF($E$22="Units",$C$22/$C$7,IF($E$22="Occupancy",$C$22*E45/SUM($E$44:$E$54),$C$22/$C$7))),0) -> 0 | K45: =SUM(F45:J45) -> 0 | L45: =K45*12 -> 0
B46: =Model!B20 -> 2 | C46: =Model!C20 -> 2b/2bath | D46: =Model!D20 -> 853 | E46: 2 | F46: =IFERROR(IF($E$18="SF",$C$18*D46/$C$8,IF($E$18="Units",$C$18/$C$7,IF($E$18="Occupancy",$C$18*E46/SUM($E$44:$E$54),$C$18/$C$7))),0) -> 0 | G46: =IFERROR(IF($E$19="SF",$C$19*D46/$C$8,IF($E$19="Units",$C$19/$C$7,IF($E$19="Occupancy",$C$19*E46/SUM($E$44:$E$54),$C$19/$C$7))),0) -> 0 | H46: =IFERROR(IF($E$20="SF",$C$20*D46/$C$8,IF($E$20="Units",$C$20/$C$7,IF($E$20="Occupancy",$C$20*E46/SUM($E$44:$E$54),$C$20/$C$7))),0) -> 0 | I46: =IFERROR(IF($E$21="SF",$C$21*D46/$C$8,IF($E$21="Units",$C$21/$C$7,IF($E$21="Occupancy",$C$21*E46/SUM($E$44:$E$54),$C$21/$C$7))),0) -> 0 | J46: =IFERROR(IF($E$22="SF",$C$22*D46/$C$8,IF($E$22="Units",$C$22/$C$7,IF($E$22="Occupancy",$C$22*E46/SUM($E$44:$E$54),$C$22/$C$7))),0) -> 0 | K46: =SUM(F46:J46) -> 0 | L46: =K46*12 -> 0
...

Sheet Equity Partner
B2: EQUITY PARTNER SUMMARY
B3: Investment Structure, Distributions & Returns Analysis
B5: INVESTMENT SUMMARY | E5: WATERFALL STRUCTURE
B6: Total Acquisition Cost | C6: =Model!D101 -> #REF! | E6: Preferred Return (Pref) | F6: =#REF! -> #REF! | G6: Annual hurdle rate
B7: (-) Total Debt | C7: =Model!D102 -> #REF!
B8: Required Equity | C8: =Model!D103 -> #REF! | E8: Pre-Pref Splits:
E9: LP Share | F9: =#REF! -> #REF!
B10: LP Equity Investment | C10: =Model!D104 -> #REF! | E10: GP Share | F10: =#REF! -> #REF!
B11: GP Equity Investment | C11: =Model!D105 -> #REF!
B12: LP Ownership % | E12: Post-Pref Splits:
B13: GP Ownership % | C13: =IFERROR(C11/C8,0) -> 0 | E13: LP Share | F13: =#REF! -> #REF!
E14: GP Promote | F14: =#REF! -> #REF!
B15: EXIT STRATEGY
B16: Exit Cap Rate | C16: =#REF! -> #REF! | E16: Gross Sale Price | F16: =IFERROR(C17/C16,0) -> 0
B17: Forward NOI at Exit | C17: =Model!F73 -> #REF! | E17: (-) Selling Costs | F17: =Model!D96
B18: Hold Period | C18: 5 | D18: Years | E18: (-) Loan Payoffs | F18: =Model!D97
E19: Net Sale Proceeds | F19: =IFERROR(F16-F17-F18,0) -> 0
B21: ANNUAL DISTRIBUTION WATERFALL
C22: Year 1 | D22: Year 2 | E22: Year 3 | F22: Year 4 | G22: Year 5 | H22: Exit | I22: Total
B23: Distributable Cash | C23: =#REF! -> #REF! | D23: =#REF! -> #REF! | E23: =#REF! -> #REF! | F23: =#REF! -> #REF! | G23: =#REF! -> #REF! | H23: =F19 -> 0 | I23: =SUM(C23:H23) -> #REF!
B25: LP Preferred Return | C25: =IFERROR($C$10*$F$6,0) -> 0 | D25: =IFERROR($C$10*$F$6,0) -> 0 | E25: =IFERROR($C$10*$F$6,0) -> 0 | F25: =IFERROR($C$10*$F$6,0) -> 0 | G25: =IFERROR($C$10*$F$6,0) -> 0 | I25: =SUM(C25:G25) -> 0
B26: LP Distribution | C26: =#REF! -> #REF! | D26: =#REF! -> #REF! | E26: =#REF! -> #REF! | F26: =#REF! -> #REF! | G26: =#REF! -> #REF! | H26: =IFERROR(H23*$F$13,0) -> 0 | I26: =SUM(C26:H26) -> #REF!
B27: GP Distribution | C27: =#REF! -> #REF! | D27: =#REF! -> #REF! | E27: =#REF! -> #REF! | F27: =#REF! -> #REF! | G27: =#REF! -> #REF! | H27: =IFERROR(H23*$F$14,0) -> 0 | I27: =SUM(C27:H27) -> #REF!
B29: Check (should = 0) | C29: =C23-C26-C27 -> #REF! | D29: =D23-D26-D27 -> #REF! | E29: =E23-E26-E27 -> #REF! | F29: =F23-F26-F27 -> #REF! | G29: =G23-G26-G27 -> #REF! | H29: =H23-H26-H27 -> 0 | I29: =I23-I26-I27 -> #REF!
B31: RETURN METRICS | G31: LP CASH FLOW SUMMARY
B32: Metric | C32: LP | D32: GP | E32: Total | G32: Item | H32: Amount
B33: Initial Investment | C33: =C10 -> #REF! | D33: =C11 -> #REF! | E33: =C8 -> #REF! | G33: Initial Investment | H33: =-C10 -> #REF! | I33: Cash Out
B34: Total Distributions | C34: =I26 -> #REF! | D34: =I27 -> #REF! | E34: =I23 -> #REF! | G34: Year 1 Distribution | H34: =C26 -> #REF! | I34: Cash In
B35: Net Profit | C35: =C34-C33 -> #REF! | D35: =D34-D33 -> #REF! | E35: =E34-E33 -> #REF! | G35: Year 2 Distribution | H35: =D26 -> #REF! | I35: Cash In
B36: Multiple on Invested Capital | C36: =IFERROR(C34/C33,0) -> 0 | D36: =IFERROR(D34/D33,0) -> 0 | E36: =IFERROR(E34/E33,0) -> 0 | G36: Year 3 Distribution | H36: =E26 -> #REF! | I36: Cash In
B37: Cash-on-Cash (Year 1) | C37: =IFERROR(C26/C33,0) -> 0 | D37: =IFERROR(C27/D33,0) -> 0 | E37: =IFERROR(C23/E33,0) -> 0 | G37: Year 4 Distribution | H37: =F26 -> #REF! | I37: Cash In
G38: Year 5 Distribution | H38: =G26 -> #REF! | I38: Cash In
B39: IRR (5-Yr Exit) | C39: =Model!C114 | D39: =Model!D114 | E39: =Model!E114 | G39: Exit Proceeds (LP Share) | H39: =H26 -> 0 | I39: Cash In
G40: Net Cash Position | H40: =SUM(H33:H39) -> #REF!
B42: COLOR LEGEND: | D42: Note: This sheet pulls data from Model sheet. Errors will resolve when Model data is populated.
B43: Green text = Linked from Model sheet
B44: Blue text = User input
B45: Black text = Calculated formula

Sheet OM DATA PARSING MAP
B2: OM DATA PARSING MAP
B3: Map incoming Offering Memorandum data to underwriting model cells
B5: INSTRUCTIONS
B6: 1. Paste OM data in Column C (Source Value)
B7: 2. Values automatically map to the Model sheet via formulas
B8: 3. Yellow cells = required inputs, Gray cells = optional
B10: OM Field Name | C10: Source Value (Paste Here) | D10: Data Type | E10: Maps To Cell | F10: Model Section | G10: Notes
B12: PROPERTY INFORMATION
B13: Property Name | D13: Text | E13: Model!D6 | F13: Key Metrics
B14: Property Address | D14: Text | E14: Model!D7 (note) | F14: Key Metrics | G14: Store in note or separate field
B15: Total Units | D15: Number | E15: Model!D7 | F15: Key Metrics | G15: Required
B16: Total Square Feet | D16: Number | E16: Model!D8 | F16: Key Metrics | G16: Building SF
B17: Year Built | D17: Number | E17: Model!D22 | F17: Assumptions
B18: Lot Size (Acres) | D18: Number | E18: - | F18: Reference | G18: Not mapped - for reference
B19: Zoning | D19: Text | E19: - | F19: Reference | G19: Not mapped - for reference
B20: Parking Spaces | D20: Number | E20: - | F20: Reference
B22: ACQUISITION / PRICING
B23: Asking Price | D23: Currency | E23: Model!D9 | F23: Key Metrics | G23: Purchase Price input
B24: Price Per Unit | D24: Currency | E24: - | F24: Calculated | G24: Auto-calculated from Price/Units
B25: Price Per SF | D25: Currency | E25: - | F25: Calculated | G25: Auto-calculated
B26: Current Cap Rate | D26: Percent | E26: - | F26: Reference | G26: Seller's stated cap
B27: Pro Forma Cap Rate | D27: Percent | E27: - | F27: Reference | G27: Seller's pro forma
B28: Closing Costs | D28: Currency | E28: Model!D23 | F28: Assumptions | G28: Estimate if not provided
B29: Due Diligence Budget | D29: Currency | E29: Model!D24 | F29: Assumptions
B30: CapEx Budget | D30: Currency | E30: Model!D25 | F30: Assumptions | G30: Renovation/deferred maint
B32: INCOME (T-12 or Pro Forma)
B33: Gross Potential Rent (Annual) | D33: Currency | E33: Model!D63 | F33: Revenue | G33: GPR from OM
B34: Vacancy Loss % | D34: Percent | E34: Model!H22 | F34: Assumptions | G34: Economic vacancy rate
B35: Loss to Lease (Annual) | D35: Currency | E35: Model!D65 | F35: Revenue | G35: Below-market leases
B36: Concessions (Annual) | D36: Currency | E36: - | F36: Reference | G36: Use % in Model!H24
B37: Bad Debt % | D37: Percent | E37: Model!H23 | F37: Assumptions
B38: Laundry Income | D38: Currency | E38: Model!C71 | F38: Revenue | G38: $/unit/month
B39: Parking Income | D39: Currency | E39: Model!C72 | F39: Revenue | G39: $/unit/month
B40: Pet Income | D40: Currency | E40: Model!C73 | F40: Revenue | G40: $/unit/month
B41: Other Income | D41: Currency | E41: Model!C74-C76 | F41: Revenue | G41: Split across line items
B42: RUBS/Utility Reimbursement | D42: Currency | E42: Model!C81-C84 | F42: Revenue | G42: If tenant-paid utilities
B44: OPERATING EXPENSES (T-12 or Pro Forma)
B45: Real Estate Taxes | D45: Currency | E45: Model!C93 | F45: Expenses | G45: Annual or $/unit/mo
B46: Property Insurance | D46: Currency | E46: Model!C94 | F46: Expenses | G46: Annual or $/unit/mo
B47: Water/Sewer | D47: Currency | E47: Model!C95 | F47: Expenses | G47: If owner-paid
...
